<?xml version="1.0" encoding="UTF-8"?>
<robot xmlns:xacro="http://www.ros.org/wiki/xacro" name="SpotMicroAI">
   <material name="white">
      <color rgba="1.0 1.0 1.0 1"/>
   </material>
   <material name="black">
      <color rgba="0.1 0.1 0.1 1" />
   </material>
   <material name="grey">
      <color rgba="0.6 0.6 0.6 1" />
   </material>
   <!-- Params -->
   <xacro:property name="body_length" value="0.160" />
   <xacro:property name="body_width" value="0.110" />
   <xacro:property name="body_height" value="0.07071" />
   <xacro:property name="lidar_length" value="0.0985" />
   <xacro:property name="lidar_width" value="0.0577" />
   <xacro:property name="lidar_height" value="0.070" />
   <xacro:property name="front_length" value="0.058" />
   <xacro:property name="rear_length" value="0.060" />
   <xacro:property name="shoulder_length" value="0.05275" />
   <xacro:property name="shoulder_width" value="0.0374" />
   <xacro:property name="leg_length" value="0.107" />
   <xacro:property name="foot_length" value="0.1185" />
   <xacro:property name="toe_radius" value="0.020" />
   <!--  <xacro:property name="toe_radius" value="0.014" /> -->
   <xacro:property name="toe_width" value="0.020" />
   <xacro:property name="shift" value="0.060" /> <!-- upper leg joint offset -->
   <xacro:property name="shiftx" value="0.105" />
   <xacro:property name="shifty" value="0.03875" />
   <!-- Macros -->
   <xacro:macro name="gen_shoulder" params="name left">
      <link name="${name}">
         <visual>
            <xacro:if value="${left}">
               <geometry>
                  <mesh filename="package://spotmicro_description/meshes/ceasar/lshoulder.stl" scale="0.001 0.001 0.001" />
               </geometry>
               <origin rpy="0 0 0" xyz="0 0 0" />
            </xacro:if>
            <xacro:unless value="${left}">
               <geometry>
                  <mesh filename="package://spotmicro_description/meshes/ceasar/rshoulder.stl" scale="0.001 0.001 0.001" />
               </geometry>
               <origin rpy="0 0 0" xyz="0 0 0" />
            </xacro:unless>
            <material name="black" />
         </visual>
         <collision>
            <geometry>
               <box size="${shoulder_length} ${shoulder_width} ${body_height}" />
            </geometry>
            <origin rpy="0 0 0" xyz="0 0 -0.01" />
         </collision>
         <inertial>
            <mass value="0.10" />
            <inertia ixx="100" ixy="0" ixz="0" iyy="100" iyz="0" izz="100" />
         </inertial>
      </link>
   </xacro:macro>
   <xacro:macro name="gen_shoulder_joint" params="pos shiftx shifty">
      <joint name="${pos}_shoulder" type="revolute">
         <parent link="base_link" />
         <child link="${pos}_shoulder_link" />
         <axis xyz="1 0 0" />
         <origin rpy="0 0 0" xyz="${shiftx} ${shifty} 0" />
         <limit effort="1000.0" velocity="0.7" lower="-0.548" upper="0.548"/>
         <dynamics damping="0.0" friction="0.5" />
      </joint>
      <transmission name="${pos}_shoulder_trans">
         <type>transmission_interface/SimpleTransmission</type>
         <joint name="${pos}_shoulder">
               <hardwareInterface>hardware_interface/PositionJointInterface</hardwareInterface>
         </joint>
         <actuator name="${pos}_shoulder_actuator">
               <hardwareInterface>hardware_interface/PositionJointInterface</hardwareInterface>
               <mechanicalReduction>1</mechanicalReduction>
         </actuator>
      </transmission>
   </xacro:macro>
   <xacro:macro name="gen_leg" params="name left">
      <link name="${name}">
         <visual>
            <xacro:if value="${left}">
               <geometry>
                  <mesh filename="package://spotmicro_description/meshes/ceasar/larm.stl" scale="0.001 0.001 0.001" />
               </geometry>
               <origin rpy="0 0 0" xyz="0 0 0" />
            </xacro:if>
            <xacro:unless value="${left}">
               <geometry>
                  <mesh filename="package://spotmicro_description/meshes/ceasar/rarm.stl" scale="0.001 0.001 0.001" />
               </geometry>
               <origin rpy="0 0 0" xyz="0 0 0" />
            </xacro:unless>
            <material name="white" />
         </visual>
         <collision>
            <origin rpy="0.0 0.0 0.0" xyz="0 0 -0.033 " />
            <geometry>
               <box size="0.028 0.050 ${leg_length}" />
            </geometry>
         </collision>
         <inertial>
            <mass value="0.15" />
            <inertia ixx="1000" ixy="0" ixz="0" iyy="1000" iyz="0" izz="1000" />
         </inertial>
      </link>
   </xacro:macro>
   <xacro:macro name="gen_leg_joint" params="pos shift">
      <joint name="${pos}_leg" type="revolute">
         <parent link="${pos}_shoulder_link" />
         <child link="${pos}_leg_link" />
         <axis xyz="0 1 0" />
         <origin rpy="0 0 0" xyz="0 ${shift} 0" />
         <limit effort="1000.0" velocity="0.5" lower="-2.666" upper="1.548"/>
         <dynamics damping="0.0" friction="0.0" />
      </joint>
      <transmission name="${pos}_leg_trans">
         <type>transmission_interface/SimpleTransmission</type>
         <joint name="${pos}_leg">
               <hardwareInterface>hardware_interface/PositionJointInterface</hardwareInterface>
         </joint>
         <actuator name="${pos}_leg_actuator">
               <hardwareInterface>hardware_interface/PositionJointInterface</hardwareInterface>
               <mechanicalReduction>1</mechanicalReduction>
         </actuator>
      </transmission>
   </xacro:macro>
   <xacro:macro name="gen_foot" params="name left">
      <link name="${name}">
         <visual>
            <xacro:if value="${left}">
               <geometry>
                  <mesh filename="package://spotmicro_description/meshes/ceasar/lfoot.stl" scale="0.001 0.001 0.001" />
               </geometry>
               <origin rpy="0 0 0" xyz="0 0 0" />
            </xacro:if>
            <xacro:unless value="${left}">
               <geometry>
                  <mesh filename="package://spotmicro_description/meshes/ceasar/rfoot.stl" scale="0.001 0.001 0.001" />
               </geometry>
               <origin rpy="0 0 0" xyz="0 0 0" />
            </xacro:unless>
            <material name="black" />
         </visual>
         <collision>
            <geometry>
               <box size="0.026 0.020 ${foot_length}" />
            </geometry>
            <origin rpy="0.0 0.0 0.0" xyz="0.0 0.0 -0.050" />
         </collision>
         <inertial>
            <mass value="0.1" />
            <inertia ixx="1000" ixy="0" ixz="0" iyy="1000" iyz="0" izz="1000" />
         </inertial>
      </link>
   </xacro:macro>
   <xacro:macro name="gen_foot_joint" params="pos">
      <joint name="${pos}_foot" type="revolute">
         <parent link="${pos}_leg_link" />
         <child link="${pos}_foot_link" />
         <axis xyz="0 1 0" />
         <origin rpy="0 0 0" xyz="0.030 0 -${leg_length}" />
         <limit effort="1000.0" velocity="0.5" lower="-2.59" upper="0.1"/>
         <dynamics damping="0.0" friction="0.5" />
      </joint>
      <transmission name="${pos}_foot_trans">
         <type>transmission_interface/SimpleTransmission</type>
         <joint name="${pos}_foot">
               <hardwareInterface>hardware_interface/PositionJointInterface</hardwareInterface>
         </joint>
         <actuator name="${pos}_foot_actuator">
               <hardwareInterface>hardware_interface/PositionJointInterface</hardwareInterface>
               <mechanicalReduction>1</mechanicalReduction>
         </actuator>
      </transmission>
   </xacro:macro>
   <xacro:macro name="gen_toe" params="name">
      <link name="${name}">
         <visual>
            <geometry>
               <mesh filename="package://spotmicro_description/meshes/ceasar/toe.stl" scale="0.001 0.001 0.001" />
            </geometry>
            <origin rpy="0 0 0" xyz="0 0 0" />
            <material name="grey" />
         </visual>
         <collision>
            <geometry>
               <sphere radius="${toe_radius}" />
            </geometry>
            <origin rpy="0 0 0" xyz="0 0 0" />
            <contact_coefficients mu="1.1" />
         </collision>
         <inertial>
            <mass value="0.05" />
            <inertia ixx="1000" ixy="0" ixz="0" iyy="1000" iyz="0" izz="1000" />
         </inertial>
      </link>
   </xacro:macro>
   <xacro:macro name="gen_toe_joint" params="pos">
      <joint name="${pos}_toe" type="fixed">
         <parent link="${pos}_foot_link" />
         <child link="${pos}_toe_link" />
         <origin xyz="-0.003 -0.012 -0.120" />
      </joint>
   </xacro:macro>
   <xacro:macro name="gen_full_leg_joint" params="pos shiftx shifty shift left">
      <xacro:gen_shoulder name="${pos}_shoulder_link" left="${left}" />
      <xacro:gen_leg name="${pos}_leg_link" left="${left}" />
      <xacro:gen_foot name="${pos}_foot_link" left="${left}" />
      <xacro:gen_toe name="${pos}_toe_link" />
      <xacro:gen_shoulder_joint pos="${pos}" shiftx="${shiftx}" shifty="${shifty}" />
      <xacro:gen_leg_joint pos="${pos}" shift="${shift}" />
      <xacro:gen_foot_joint pos="${pos}" />
      <xacro:gen_toe_joint pos="${pos}" />
   </xacro:macro>
   <!-- Robot Body -->
   <link name="base_link"/>
   <link name="base_inertia">
      <visual>
         <geometry>
            <mesh filename="package://spotmicro_description/meshes/ceasar/mainbody.stl" scale="0.001 0.001 0.001" />
         </geometry>
         <material name="black" />
         <origin rpy="0 0 0" xyz="0 0 0" />
      </visual>
      <collision>
         <geometry>
            <box size="${body_length} ${body_width} ${body_height}" />
         </geometry>
         <origin rpy="0 0 0" xyz="0 0 -0.010" />
      </collision>
      <inertial>
         <mass value="2.80" />
         <inertia ixx="100" ixy="0" ixz="0" iyy="100" iyz="0" izz="100" />
      </inertial>
   </link>
   <joint name="base_inertia_joint" type="fixed">
      <parent link="base_link" />
      <child link="base_inertia" />
   </joint>
   <link name="rear_link">
      <visual>
         <geometry>
            <mesh filename="package://spotmicro_description/meshes/ceasar/backpart.stl" scale="0.001 0.001 0.001" />
         </geometry>
         <origin rpy="0 0 0" xyz="-0.033598 -0.054006 0.004128" />
         <material name="white" />
      </visual>
      <collision>
         <geometry>
            <box size="${rear_length} ${body_width} ${body_height}" />
         </geometry>
         <origin rpy="0 0 0" xyz="-0.158 0 -0.010" />
      </collision>
      <inertial>
         <mass value="0.20" />
         <inertia ixx="100" ixy="0" ixz="0" iyy="100" iyz="0" izz="100" />
      </inertial>
   </link>
   <joint name="base_rear" type="fixed">
      <parent link="base_link" />
      <child link="rear_link" />
   </joint>
   <gazebo reference="rear_link">
      <material>Gazebo/white</material>
   </gazebo>
   <link name="front_link">
      <visual>
         <geometry>
            <mesh filename="package://spotmicro_description/meshes/ceasar/frontpart.stl" scale="0.001 0.001 0.001" />
         </geometry>
         <origin rpy="0 0 0" xyz="0.185533 0.05675 -0.046798" />
         <material name="white" />
      </visual>
      <collision>
         <geometry>
            <box size="${front_length} ${body_width} ${body_height}" />
         </geometry>
         <origin rpy="0 0 0" xyz="0.158 0 -0.010" />
      </collision>
      <inertial>
         <mass value="0.20" />
         <inertia ixx="100" ixy="0" ixz="0" iyy="100" iyz="0" izz="100" />
      </inertial>
   </link>
   <gazebo reference="front_link">
      <material>Gazebo/white</material>
   </gazebo>
   <joint name="base_front" type="fixed">
      <parent link="base_link" />
      <child link="front_link" />
   </joint>
   <!-- create Legs -->
   <xacro:gen_full_leg_joint pos="front_left" shiftx="${shiftx}" shifty="${shifty}" shift="${shift}" left="true" />
   <xacro:gen_full_leg_joint pos="rear_left" shiftx="-${shiftx}" shifty="${shifty}" shift="${shift}" left="true" />
   <xacro:gen_full_leg_joint pos="front_right" shiftx="${shiftx}" shifty="-${shifty}" shift="-${shift}" left="false" />
   <xacro:gen_full_leg_joint pos="rear_right" shiftx="-${shiftx}" shifty="-${shifty}" shift="-${shift}" left="false" />
</robot>